<mujoco>
	<option gravity="0 0 -9.81" integrator="RK4">
		<flag energy="enable"/>
	</option>
	
	<worldbody>
		<light diffuse=".5 .5 .5" pos="0 0 3" dir="0 0 -1"/>
		<geom type="plane" size="2 2 .1" rgba="1 1 1 1"/>
		<body pos="0 0 3" euler="0 10 0">
			<joint name="pin" type="hinge" axis="0 1 0" pos="0 0 -.5"/>
			<geom type="cylinder" size=".05 .5" rgba="1 0 0 1" mass="1"/>
			
			<!--Moved a bit by y-axis to prevent collision-->
			<body pos="0 0.1 1" euler="0 0 0">
				<joint name="pin2" type="hinge" axis="0 1 0" pos="0 0 -0.5"/>
				<geom type="cylinder" size="0.05 0.5" rgba="0 1 0 1" mass="1"/>
 			</body> 
		
		</body> 
	</worldbody>
	<!-- <actuator>
		Motor gets to know joint from the joint name
		<motor joint="pin" name="torque" gear="1" ctrllimited="true" ctrlrange="-100 100"/> 
		<position name="position_servo" joint="pin" kp="0"/>
		<velocity name="velocity servo" joint="pin" kv="0"/>
	</actuator>
	<sensor>
		<jointpos joint="pin" noise="0.2"/>
		<jointvel joint="pin" noise="1"/>
	</sensor> -->
</mujoco>


